
=========================================
 TREND  KEYWORDS SEND - EXEPTION:
('Connection aborted.', RemoteDisconnected('Remote end closed connection without response'))
Traceback (most recent call last):
  File "C:\Users\Deadvin\PycharmProjects\Web_scraper\venv\lib\site-packages\urllib3\connectionpool.py", line 703, in urlopen
    httplib_response = self._make_request(
  File "C:\Users\Deadvin\PycharmProjects\Web_scraper\venv\lib\site-packages\urllib3\connectionpool.py", line 449, in _make_request
    six.raise_from(e, None)
  File "<string>", line 3, in raise_from
  File "C:\Users\Deadvin\PycharmProjects\Web_scraper\venv\lib\site-packages\urllib3\connectionpool.py", line 444, in _make_request
    httplib_response = conn.getresponse()
  File "C:\Users\Deadvin\AppData\Local\Programs\Python\Python39\lib\http\client.py", line 1345, in getresponse
    response.begin()
  File "C:\Users\Deadvin\AppData\Local\Programs\Python\Python39\lib\http\client.py", line 307, in begin
    version, status, reason = self._read_status()
  File "C:\Users\Deadvin\AppData\Local\Programs\Python\Python39\lib\http\client.py", line 276, in _read_status
    raise RemoteDisconnected("Remote end closed connection without"
http.client.RemoteDisconnected: Remote end closed connection without response

During handling of the above exception, another exception occurred:

Traceback (most recent call last):
  File "C:\Users\Deadvin\PycharmProjects\Web_scraper\venv\lib\site-packages\requests\adapters.py", line 489, in send
    resp = conn.urlopen(
  File "C:\Users\Deadvin\PycharmProjects\Web_scraper\venv\lib\site-packages\urllib3\connectionpool.py", line 787, in urlopen
    retries = retries.increment(
  File "C:\Users\Deadvin\PycharmProjects\Web_scraper\venv\lib\site-packages\urllib3\util\retry.py", line 550, in increment
    raise six.reraise(type(error), error, _stacktrace)
  File "C:\Users\Deadvin\PycharmProjects\Web_scraper\venv\lib\site-packages\urllib3\packages\six.py", line 769, in reraise
    raise value.with_traceback(tb)
  File "C:\Users\Deadvin\PycharmProjects\Web_scraper\venv\lib\site-packages\urllib3\connectionpool.py", line 703, in urlopen
    httplib_response = self._make_request(
  File "C:\Users\Deadvin\PycharmProjects\Web_scraper\venv\lib\site-packages\urllib3\connectionpool.py", line 449, in _make_request
    six.raise_from(e, None)
  File "<string>", line 3, in raise_from
  File "C:\Users\Deadvin\PycharmProjects\Web_scraper\venv\lib\site-packages\urllib3\connectionpool.py", line 444, in _make_request
    httplib_response = conn.getresponse()
  File "C:\Users\Deadvin\AppData\Local\Programs\Python\Python39\lib\http\client.py", line 1345, in getresponse
    response.begin()
  File "C:\Users\Deadvin\AppData\Local\Programs\Python\Python39\lib\http\client.py", line 307, in begin
    version, status, reason = self._read_status()
  File "C:\Users\Deadvin\AppData\Local\Programs\Python\Python39\lib\http\client.py", line 276, in _read_status
    raise RemoteDisconnected("Remote end closed connection without"
urllib3.exceptions.ProtocolError: ('Connection aborted.', RemoteDisconnected('Remote end closed connection without response'))

During handling of the above exception, another exception occurred:

Traceback (most recent call last):
  File "C:\Users\Deadvin\PycharmProjects\Web_scraper\twitter_stream_all_v1.py", line 410, in send_key_trend
    requests.get(api_url + "ren_trends", verify=False)
  File "C:\Users\Deadvin\PycharmProjects\Web_scraper\venv\lib\site-packages\requests\api.py", line 73, in get
    return request("get", url, params=params, **kwargs)
  File "C:\Users\Deadvin\PycharmProjects\Web_scraper\venv\lib\site-packages\requests\api.py", line 59, in request
    return session.request(method=method, url=url, **kwargs)
  File "C:\Users\Deadvin\PycharmProjects\Web_scraper\venv\lib\site-packages\requests\sessions.py", line 587, in request
    resp = self.send(prep, **send_kwargs)
  File "C:\Users\Deadvin\PycharmProjects\Web_scraper\venv\lib\site-packages\requests\sessions.py", line 701, in send
    r = adapter.send(request, **kwargs)
  File "C:\Users\Deadvin\PycharmProjects\Web_scraper\venv\lib\site-packages\requests\adapters.py", line 547, in send
    raise ConnectionError(err, request=request)
requests.exceptions.ConnectionError: ('Connection aborted.', RemoteDisconnected('Remote end closed connection without response'))

=========================================